Workbook

Sheet README_FIRST
A1: EXCEL ADVANCED FUNCTIONS - DEMONSTRATION FILE
A2: HPCL Trip Data Analysis Using Excel Functions from Class 8-9-10-11
A4: ABOUT THIS FILE:
A6: This Excel workbook demonstrates 6 advanced Excel functions using real HPCL logistics data.
A7: Each function is implemented in a separate sheet with:
A8: • Actual function formulas displayed (column E)
A9: • Detailed descriptions of how each function works
A10: • Calculated results shown side-by-side with input data
A11: • Cell comments for quick reference
A13: QUICK NAVIGATION:
A14: Sheet 1: README_FIRST - This file (you are here)
A15: Sheet 2: Functions_Guide - Quick reference of all functions
... A24: FUNCTION SUMMARY TABLE:
A25: Function Name | B25: Category | C25: Use Case | D25: Syntax
A26: CONCATENATE | B26: Text Function | C26: Join multiple text strings together | D26: CONCATENATE(text1, text2, ...)
A27: CHOOSE | B27: Lookup Function | C27: Select value from list based on index number | D27: CHOOSE(index_number, value1, value2, ...)
A28: RANK/MATCH | B28: Lookup Function | C28: Find position/rank of a value in a range | D28: RANK(value, range, order)
A29: INDEX | B29: Array Function | C29: Return value from specific position in array | D29: INDEX(array, row_number)
A30: INDEX-MATCH | B30: Hybrid Function | C30: Lookup value without using VLOOKUP | D30: INDEX(array, MATCH(lookup_value, lookup_array, 0))
A31: AVERAGE/MAX/MIN | B31: Statistical Function | C31: Calculate summary statistics | D31: AVERAGE(range) / MAX(range) / MIN(range)
A34: KEY FEATURES:
A35: ✓ All formulas use cell references (not hardcoded values)
A36: ✓ Formulas are locked with $ signs for proper copying
A37: ✓ Cross-sheet references to Original_Data for data integrity
A38: ✓ Color-coded display: Yellow background = formula section
A39: ✓ Each sheet has comments explaining the operations
A40: ✓ Real HPCL logistics data with 49 trip records
A41: ✓ Ready for classroom demonstration and learning

Sheet Functions_Guide
A1: EXCEL FUNCTIONS DEMONSTRATION GUIDE
A3: Sheet Name | B3: Function Used | C3: Purpose | D3: Formula Example
A4: CONCATENATE | B4: CONCATENATE(text1, text2, ...) | C4: Joins separate text values into one | D4: =CONCATENATE(A2," - ",TEXT(B2,"MM/DD/YYYY")) -> - 01/00/1900
A5: CHOOSE_FuelCategory | B5: CHOOSE(index, val1, val2, ...) | C5: Selects value from list based on index | D5: =IF(B2<=3,CHOOSE(1,"Low"),IF(B2<=3.5,CHOOSE(2,"Medium"),CHOOSE(3,"High"))) -> Low
A6: MATCH_Ranking | B6: RANK(value, range, order) | C6: Returns rank of a value in a list | D6: =RANK(B2,$B$2:$B$50,0) -> #N/A
A7: INDEX_Extract | B7: INDEX(array, row_number) | C7: Returns value from specific position in array | D7: =INDEX(Original_Data!$A$2:$A$50,1) -> TRP-00001
A8: INDEX_MATCH | B8: INDEX-MATCH combination | C8: Looks up value using INDEX and MATCH together | D8: =INDEX(Original_Data!$H$2:$H$50,MATCH(A2,Original_Data!$A$2:$A$50,0)) -> #N/A
A9: Statistics | B9: AVERAGE, MAX, MIN, COUNTA | C9: Calculates summary statistics | D9: =AVERAGE(Original_Data!$H$2:$H$50) -> 55.204082

Sheet Pivot
A1: Trip_ID | B1: All
B3: Column Labels
B4: 3rd Party Logistics | C4: Company Owned | D4: Grand Total
A5: Sum of Fuel_Efficiency_KMPL | B5: 82.63 | C5: 85.45 | D5: 168.08

Sheet Pivot_and Charts
A3: Row Labels | B3: Sum of Fuel_Efficiency_KMPL | C3: Sum of IoT_Tire_Pressure_PSI
A4: 3rd Party Logistics | B4: 82.63 | C4: 2493
A5: Company Owned | B5: 85.45 | C5: 2594
A6: Grand Total | B6: 168.08 | C6: 5087

Sheet Original_Data
A1: Trip_ID | B1: Date | C1: Vendor_Type | D1: Avg_Speed_Kmph | E1: IoT_Tire_Pressure_PSI | F1: Harsh_Braking_Count | G1: Fuel_Efficiency_KMPL | H1: Delivery_Delay_Mins
A2: TRP-00001 | B2: 19-02-2023 18:41 | C2: 3rd Party Logistics | D2: 63.7 | E2: 106 | F2: 2 | G2: 2.67 | H2: 30
A3: TRP-00002 | B3: 24-06-2023 12:23 | C3: Company Owned | D3: 66.2 | E3: 100 | F3: 6 | G3: 3.84 | H3: 57
A4: TRP-00003 | B4: 20-03-2023 05:53 | C4: 3rd Party Logistics | D4: 57 | E4: 91 | F4: 6 | G4: 3.32 | H4: 82
A5: TRP-00004 | B5: 25-06-2023 09:58 | C5: Company Owned | D5: 56.7 | E5: 95 | F5: 6 | G5: 3.44 | H5: 41
A6: TRP-00005 | B6: 15-12-2023 18:22 | C6: Company Owned | D6: 62 | E6: 111 | F6: 5 | G6: 2.6 | H6: 71
A7: TRP-00006 | B7: 18-03-2023 14:57 | C7: 3rd Party Logistics | D7: 66.2 | E7: 103 | F7: 7 | G7: 2.88 | H7: 117
A8: TRP-00007 | B8: 19-01-2023 22:37 | C8: Company Owned | D8: 55.4 | E8: 92 | F8: 2 | G8: 4.08 | H8: 39
A9: TRP-00008 | B9: 25-06-2023 01:30 | C9: 3rd Party Logistics | D9: 50 | E9: 101 | F9: 5 | G9: 3.41 | H9: 45
A10: TRP-00009 | B10: 27-10-2023 10:48 | C10: 3rd Party Logistics | D10: 61.5 | E10: 93 | F10: 4 | G10: 3.1 | H10: 73
A11: TRP-00010 | B11: 45145.844 | C11: Company Owned | D11: 36.4 | E11: 101 | F11: 6 | G11: 3.27 | H11: -8
A12: TRP-00011 | B12: 23-07-2023 11:04 | C12: Company Owned | D12: 64.1 | E12: 102 | F12: 4 | G12: 4.21 | H12: 0
A13: TRP-00012 | B13: 28-04-2023 02:21 | C13: 3rd Party Logistics | D13: 47.9 | E13: 91 | F13: 6 | G13: 4 | H13: 100
A14: TRP-00013 | B14: 27-07-2023 14:51 | C14: Company Owned | D14: 52.6 | E14: 91 | F14: 1 | G14: 3.04 | H14: 45
A15: TRP-00014 | B15: 45117.483 | C15: 3rd Party Logistics | D15: 64.2 | E15: 104 | F15: 5 | G15: 2.74 | H15: -1
A16: TRP-00015 | B16: 45261.989 | C16: 3rd Party Logistics | D16: 50.8 | E16: 112 | F16: 5 | G16: 3 | H16: 115
A17: TRP-00016 | B17: 22-07-2023 21:38 | C17: 3rd Party Logistics | D17: 61.5 | E17: 118 | F17: 7 | G17: 4.34 | H17: 86
A18: TRP-00017 | B18: 24-10-2023 04:03 | C18: Company Owned | D18: 66.4 | E18: 106 | F18: 0 | G18: 3.66 | H18: 38
A19: TRP-00018 | B19: 45267.809 | C19: Company Owned | D19: 56.1 | E19: 96 | F19: 3 | G19: 3.57 | H19: -2
A20: TRP-00019 | B20: 15-04-2023 12:42 | C20: Company Owned | D20: 58.1 | E20: 119 | F20: 2 | G20: 3.69 | H20: 20
A21: TRP-00020 | B21: 30-03-2023 02:17 | C21: Company Owned | D21: 53.8 | E21: 117 | F21: 0 | G21: 3.23 | H21: 89
A22: TRP-00021 | B22: 16-04-2023 23:28 | C22: 3rd Party Logistics | D22: 56.2 | E22: 103 | F22: 5 | G22: 4.11 | H22: 66
A23: TRP-00022 | B23: 26-08-2023 01:25 | C23: 3rd Party Logistics | D23: 43.8 | E23: 101 | F23: 0 | G23: 3.55 | H23: 51
A24: TRP-00023 | B24: 45144.828 | C24: Company Owned | D24: 52.1 | E24: 119 | F24: 1 | G24: 2.73 | H24: -6
A25: TRP-00024 | B25: 16-06-2023 08:51 | C25: Company Owned | D25: 42.1 | E25: 106 | F25: 3 | G25: 2.76 | H25: 33
A26: TRP-00025 | B26: 44988.081 | C26: Company Owned | D26: 46 | E26: 103 | F26: 7 | G26: 3.57 | H26: 95
A27: TRP-00026 | B27: 44968.231 | C27: 3rd Party Logistics | D27: 35 | E27: 95 | F27: 5 | G27: 4.37 | H27: 49
A28: TRP-00027 | B28: 13-09-2023 20:13 | C28: Company Owned | D28: 57.6 | E28: 108 | F28: 5 | G28: 3.12 | H28: 41
A29: TRP-00028 | B29: 26-03-2023 04:00 | C29: 3rd Party Logistics | D29: 71.9 | E29: 113 | F29: 2 | G29: 4.24 | H29: 11
A30: TRP-00029 | B30: 23-06-2023 20:25 | C30: Company Owned | D30: 50.4 | E30: 95 | F30: 7 | G30: 4.03 | H30: 97
A31: TRP-00030 | B31: 21-01-2023 09:01 | C31: 3rd Party Logistics | D31: 64.7 | E31: 116 | F31: 7 | G31: 3 | H31: 117
A32: TRP-00031 | B32: 45242.327 | C32: 3rd Party Logistics | D32: 66.3 | E32: 107 | F32: 6 | G32: 2.57 | H32: 55
A33: TRP-00032 | B33: 45201.993 | C33: Company Owned | D33: 43 | E33: 113 | F33: 3 | G33: 2.7 | H33: 67
A34: TRP-00033 | B34: 45142.622 | C34: Company Owned | D34: 45.2 | E34: 94 | F34: 1 | G34: 3.96 | H34: 41
A35: TRP-00034 | B35: 45117.711 | C35: 3rd Party Logistics | D35: 64.9 | E35: 113 | F35: 4 | G35: 2.9 | H35: 104
A36: TRP-00035 | B36: 23-02-2023 08:35 | C36: Company Owned | D36: 54.1 | E36: 113 | F36: 0 | G36: 3.24 | H36: 77
A37: TRP-00036 | B37: 27-10-2023 13:12 | C37: 3rd Party Logistics | D37: 42.1 | E37: 95 | F37: 7 | G37: 3.5 | H37: -1
A38: TRP-00037 | B38: 17-02-2023 21:48 | C38: 3rd Party Logistics | D38: 48.6 | E38: 91 | F38: 2 | G38: 3.95 | H38: 95
A39: TRP-00038 | B39: 45053.029 | C39: 3rd Party Logistics | D39: 59.2 | E39: 97 | F39: 5 | G39: 2.73 | H39: 85
A40: TRP-00039 | B40: 44988.942 | C40: 3rd Party Logistics | D40: 47.1 | E40: 104 | F40: 4 | G40: 3.31 | H40: 103
...

Sheet Power_Query_inserting text file
A1: ID | B1: Name | C1: Age | D1: Gender | E1: Custom column
A2: 101 | B2: Joe | C2: 26 | D2: M | E2: Not Targeted
A3: 132 | B3: Beth | C3: 43 | D3: F | E3: Young
A4: 123 | B4: Nancy | C4: 32 | D4: F | E4: Young
A5: 131 | B5: Dave | C5: 42 | D5: M | E5: Young
A6: 108 | B6: Nathan | C6: 35 | D6: M | E6: Young
A7: 110 | B7: Betty | C7: 18 | D7: F | E7: Not Targeted

Sheet CONCATENATE
A1: Trip_ID | B1: Date | C1: Combined_Result | D1: Concatenate | E1: FORMULA USED:
A2: TRP-00001 | B2: 19-02-2023 18:41 | C2: TRP-00001 - 02/19/2023 | D2: =CONCATENATE(A2," ",B2) -> TRP-00001 19-02-2023 18:41 | E2: =CONCATENATE(A2," - ",TEXT(B2,"MM/DD/YYYY")) -> TRP-00001 - 19-02-2023 18:41
A3: TRP-00002 | B3: 24-06-2023 12:23 | C3: TRP-00002 - 06/24/2023 | D3: =CONCATENATE(A3," ",B3) -> TRP-00002 24-06-2023 12:23 | E3: DESCRIPTION:
A4: TRP-00003 | B4: 20-03-2023 05:53 | C4: TRP-00003 - 03/20/2023 | D4: =CONCATENATE(A4," ",B4) -> TRP-00003 20-03-2023 05:53 | E4: This formula combines Trip_ID from column A with a formatted date from column B. The CONCATENATE function joins text strings, and TEXT function formats the date as MM/DD/YYYY.
A5: TRP-00004 | B5: 25-06-2023 09:58 | C5: TRP-00004 - 06/25/2023 | D5: =CONCATENATE(A5," ",B5) -> TRP-00004 25-06-2023 09:58
A6: TRP-00005 | B6: 15-12-2023 18:22 | C6: TRP-00005 - 12/15/2023 | D6: =CONCATENATE(A6," ",B6) -> TRP-00005 15-12-2023 18:22
A7: TRP-00006 | B7: 18-03-2023 14:57 | C7: TRP-00006 - 03/18/2023 | D7: =CONCATENATE(A7," ",B7) -> TRP-00006 18-03-2023 14:57
A8: TRP-00007 | B8: 19-01-2023 22:37 | C8: TRP-00007 - 01/19/2023 | D8: =CONCATENATE(A8," ",B8) -> TRP-00007 19-01-2023 22:37
A9: TRP-00008 | B9: 25-06-2023 01:30 | C9: TRP-00008 - 06/25/2023 | D9: =CONCATENATE(A9," ",B9) -> TRP-00008 25-06-2023 01:30
A10: TRP-00009 | B10: 27-10-2023 10:48 | C10: TRP-00009 - 10/27/2023 | D10: =CONCATENATE(A10," ",B10) -> TRP-00009 27-10-2023 10:48
A11: TRP-00010 | B11: 45145.844 | C11: TRP-00010 - 08/07/2023 | D11: =CONCATENATE(A11," ",B11) -> TRP-00010 45145.8444444444
A12: TRP-00011 | B12: 23-07-2023 11:04 | C12: TRP-00011 - 07/23/2023 | D12: =CONCATENATE(A12," ",B12) -> TRP-00011 23-07-2023 11:04
A13: TRP-00012 | B13: 28-04-2023 02:21 | C13: TRP-00012 - 04/28/2023 | D13: =CONCATENATE(A13," ",B13) -> TRP-00012 28-04-2023 02:21
A14: TRP-00013 | B14: 27-07-2023 14:51 | C14: TRP-00013 - 07/27/2023 | D14: =CONCATENATE(A14," ",B14) -> TRP-00013 27-07-2023 14:51
A15: TRP-00014 | B15: 45117.483 | C15: TRP-00014 - 07/10/2023 | D15: =CONCATENATE(A15," ",B15) -> TRP-00014 45117.4826388889
A16: TRP-00015 | B16: 45261.989 | C16: TRP-00015 - 12/01/2023 | D16: =CONCATENATE(A16," ",B16) -> TRP-00015 45261.9888888889
A17: TRP-00016 | B17: 22-07-2023 21:38 | C17: TRP-00016 - 07/22/2023 | D17: =CONCATENATE(A17," ",B17) -> TRP-00016 22-07-2023 21:38
A18: TRP-00017 | B18: 24-10-2023 04:03 | C18: TRP-00017 - 10/24/2023 | D18: =CONCATENATE(A18," ",B18) -> TRP-00017 24-10-2023 04:03
A19: TRP-00018 | B19: 45267.809 | C19: TRP-00018 - 12/07/2023 | D19: =CONCATENATE(A19," ",B19) -> TRP-00018 45267.8090277778
A20: TRP-00019 | B20: 15-04-2023 12:42 | C20: TRP-00019 - 04/15/2023 | D20: =CONCATENATE(A20," ",B20) -> TRP-00019 15-04-2023 12:42
A21: TRP-00020 | B21: 30-03-2023 02:17 | C21: TRP-00020 - 03/30/2023 | D21: =CONCATENATE(A21," ",B21) -> TRP-00020 30-03-2023 02:17
A22: TRP-00021 | B22: 16-04-2023 23:28 | C22: TRP-00021 - 04/16/2023 | D22: =CONCATENATE(A22," ",B22) -> TRP-00021 16-04-2023 23:28
A23: TRP-00022 | B23: 26-08-2023 01:25 | C23: TRP-00022 - 08/26/2023 | D23: =CONCATENATE(A23," ",B23) -> TRP-00022 26-08-2023 01:25
A24: TRP-00023 | B24: 45144.828 | C24: TRP-00023 - 08/06/2023 | D24: =CONCATENATE(A24," ",B24) -> TRP-00023 45144.8284722222
A25: TRP-00024 | B25: 16-06-2023 08:51 | C25: TRP-00024 - 06/16/2023 | D25: =CONCATENATE(A25," ",B25) -> TRP-00024 16-06-2023 08:51
A26: TRP-00025 | B26: 44988.081 | C26: TRP-00025 - 03/03/2023 | D26: =CONCATENATE(A26," ",B26) -> TRP-00025 44988.08125
A27: TRP-00026 | B27: 44968.231 | C27: TRP-00026 - 02/11/2023 | D27: =CONCATENATE(A27," ",B27) -> TRP-00026 44968.23125
A28: TRP-00027 | B28: 13-09-2023 20:13 | C28: TRP-00027 - 09/13/2023 | D28: =CONCATENATE(A28," ",B28) -> TRP-00027 13-09-2023 20:13
A29: TRP-00028 | B29: 26-03-2023 04:00 | C29: TRP-00028 - 03/26/2023 | D29: =CONCATENATE(A29," ",B29) -> TRP-00028 26-03-2023 04:00
A30: TRP-00029 | B30: 23-06-2023 20:25 | C30: TRP-00029 - 06/23/2023 | D30: =CONCATENATE(A30," ",B30) -> TRP-00029 23-06-2023 20:25
A31: TRP-00030 | B31: 21-01-2023 09:01 | C31: TRP-00030 - 01/21/2023 | D31: =CONCATENATE(A31," ",B31) -> TRP-00030 21-01-2023 09:01
A32: TRP-00031 | B32: 45242.327 | C32: TRP-00031 - 11/12/2023 | D32: =CONCATENATE(A32," ",B32) -> TRP-00031 45242.3270833333
A33: TRP-00032 | B33: 45201.993 | C33: TRP-00032 - 10/02/2023 | D33: =CONCATENATE(A33," ",B33) -> TRP-00032 45201.9930555555
A34: TRP-00033 | B34: 45142.622 | C34: TRP-00033 - 08/04/2023 | D34: =CONCATENATE(A34," ",B34) -> TRP-00033 45142.6222222222
A35: TRP-00034 | B35: 45117.711 | C35: TRP-00034 - 07/10/2023 | D35: =CONCATENATE(A35," ",B35) -> TRP-00034 45117.7111111111
A36: TRP-00035 | B36: 23-02-2023 08:35 | C36: TRP-00035 - 02/23/2023 | D36: =CONCATENATE(A36," ",B36) -> TRP-00035 23-02-2023 08:35
A37: TRP-00036 | B37: 27-10-2023 13:12 | C37: TRP-00036 - 10/27/2023 | D37: =CONCATENATE(A37," ",B37) -> TRP-00036 27-10-2023 13:12
A38: TRP-00037 | B38: 17-02-2023 21:48 | C38: TRP-00037 - 02/17/2023 | D38: =CONCATENATE(A38," ",B38) -> TRP-00037 17-02-2023 21:48
A39: TRP-00038 | B39: 45053.029 | C39: TRP-00038 - 05/07/2023 | D39: =CONCATENATE(A39," ",B39) -> TRP-00038 45053.0291666667
A40: TRP-00039 | B40: 44988.942 | C40: TRP-00039 - 03/03/2023 | D40: =CONCATENATE(A40," ",B40) -> TRP-00039 44988.9423611111
...

Sheet CHOOSE_FuelCategory
A1: Trip_ID | B1: Fuel_Efficiency_KMPL | C1: Fuel_Category | D1: Category | E1: FORMULA USED:
A2: TRP-00001 | B2: 2.67 | C2: Low | D2: =IF(B2<=3,"Low",IF(B2<=3.5,"Medium","High")) -> Low | E2: =IF(B2<=3,CHOOSE(1,"Low"),IF(B2<=3.5,CHOOSE(2,"Medium"),CHOOSE(3,"High"))) -> Low
A3: TRP-00002 | B3: 3.84 | C3: High | D3: =IF(B3<=3,"Low",IF(B3<=3.5,"Medium","High")) -> High | E3: DESCRIPTION:
A4: TRP-00003 | B4: 3.32 | C4: Medium | D4: =IF(B4<=3,"Low",IF(B4<=3.5,"Medium","High")) -> Medium | E4: CHOOSE function selects from a list based on index. Combined with IF statements: Low (≤3), Medium (3-3.5), High (>3.5) KMPL. Index 1=Low, 2=Medium, 3=High.
A5: TRP-00004 | B5: 3.44 | C5: Medium | D5: =IF(B5<=3,"Low",IF(B5<=3.5,"Medium","High")) -> Medium
A6: TRP-00005 | B6: 2.6 | C6: Low | D6: =IF(B6<=3,"Low",IF(B6<=3.5,"Medium","High")) -> Low
A7: TRP-00006 | B7: 2.88 | C7: Low | D7: =IF(B7<=3,"Low",IF(B7<=3.5,"Medium","High")) -> Low
A8: TRP-00007 | B8: 4.08 | C8: High | D8: =IF(B8<=3,"Low",IF(B8<=3.5,"Medium","High")) -> High
A9: TRP-00008 | B9: 3.41 | C9: Medium | D9: =IF(B9<=3,"Low",IF(B9<=3.5,"Medium","High")) -> Medium
A10: TRP-00009 | B10: 3.1 | C10: Medium | D10: =IF(B10<=3,"Low",IF(B10<=3.5,"Medium","High")) -> Medium
A11: TRP-00010 | B11: 3.27 | C11: Medium | D11: =IF(B11<=3,"Low",IF(B11<=3.5,"Medium","High")) -> Medium
A12: TRP-00011 | B12: 4.21 | C12: High | D12: =IF(B12<=3,"Low",IF(B12<=3.5,"Medium","High")) -> High
A13: TRP-00012 | B13: 4 | C13: High | D13: =IF(B13<=3,"Low",IF(B13<=3.5,"Medium","High")) -> High
A14: TRP-00013 | B14: 3.04 | C14: Medium | D14: =IF(B14<=3,"Low",IF(B14<=3.5,"Medium","High")) -> Medium
A15: TRP-00014 | B15: 2.74 | C15: Low | D15: =IF(B15<=3,"Low",IF(B15<=3.5,"Medium","High")) -> Low
A16: TRP-00015 | B16: 3 | C16: Low | D16: =IF(B16<=3,"Low",IF(B16<=3.5,"Medium","High")) -> Low
... A50: TRP-00049 | B50: 2.78 | C50: Low | D50: =IF(B50<=3,"Low",IF(B50<=3.5,"Medium","High")) -> Low

Sheet MATCH_Ranking
A1: Trip_ID | B1: Delivery_Delay_Mins | C1: Delay_Rank | D1: rank | E1: FORMULA USED:
A2: TRP-00001 | B2: 30 | C2: 36 | D2: =RANK(B2,$B$2:$B$50,0) -> 36 | E2: =RANK(B2,$B$2:$B$50,0) -> 36
A3: TRP-00002 | B3: 57 | C3: 24 | D3: =RANK(B3,$B$2:$B$50,0) -> 23 | E3: DESCRIPTION:
A4: TRP-00003 | B4: 82 | C4: 16 | D4: =RANK(B4,$B$2:$B$50,0) -> 16 | E4: RANK function returns position of a value within a sorted range. 0=descending (highest value gets rank 1). $ signs lock the range. Shows which trips had worst (rank 1) to best delivery delays.
A5: TRP-00004 | B5: 41 | C5: 32 | D5: =RANK(B5,$B$2:$B$50,0) -> 30
A6: TRP-00005 | B6: 71 | C6: 19 | D6: =RANK(B6,$B$2:$B$50,0) -> 19
A7: TRP-00006 | B7: 117 | C7: 2 | D7: =RANK(B7,$B$2:$B$50,0) -> 1
A8: TRP-00007 | B8: 39 | C8: 33 | D8: =RANK(B8,$B$2:$B$50,0) -> 33
A9: TRP-00008 | B9: 45 | C9: 29 | D9: =RANK(B9,$B$2:$B$50,0) -> 28
A10: TRP-00009 | B10: 73 | C10: 18 | D10: =RANK(B10,$B$2:$B$50,0) -> 18
A11: TRP-00010 | B11: -8 | C11: 49 | D11: =RANK(B11,$B$2:$B$50,0) -> 49
A12: TRP-00011 | B12: 0 | C12: 43 | D12: =RANK(B12,$B$2:$B$50,0) -> 43
A13: TRP-00012 | B13: 100 | C13: 9 | D13: =RANK(B13,$B$2:$B$50,0) -> 9
A14: TRP-00013 | B14: 45 | C14: 29 | D14: =RANK(B14,$B$2:$B$50,0) -> 28
A15: TRP-00014 | B15: -1 | C15: 45 | D15: =RANK(B15,$B$2:$B$50,0) -> 44
A16: TRP-00015 | B16: 115 | C16: 4 | D16: =RANK(B16,$B$2:$B$50,0) -> 3
... A50: TRP-00049 | B50: -7 | C50: 48 | D50: =RANK(B50,$B$2:$B$50,0) -> 48

Sheet INDEX_Extract
A1: Row_Num | B1: Trip_ID | C1: Avg_Speed_Kmph | D1: Tire_Pressure_PSI | E1: Index tire pressure | G1: FORMULA USED:
A2: 1 | B2: TRP-00001 | C2: 63.7 | D2: 106 | E2: =INDEX(Original_Data!$E$2:$E$50,1) -> 106 | F2: =INDEX($A$1:$E$11,2,3) -> 63.7 | G2: =INDEX(Original_Data!$A$2:$A$50,1) -> TRP-00001
A3: 2 | B3: TRP-00002 | C3: 66.2 | D3: 100 | E3: =INDEX(Original_Data!$E$2:$E$50,2) -> 100 | G3: DESCRIPTION:
A4: 3 | B4: TRP-00003 | C4: 57 | D4: 91 | E4: =INDEX(Original_Data!$E$2:$E$50,3) -> 91 | G4: INDEX function returns value from specific position in an array. First parameter = data range, second = row position. Used to extract data by row number from Original_Data sheet.
A5: 4 | B5: TRP-00004 | C5: 56.7 | D5: 95 | E5: =INDEX(Original_Data!$E$2:$E$50,4) -> 95
A6: 5 | B6: TRP-00005 | C6: 62 | D6: 111 | E6: =INDEX(Original_Data!$E$2:$E$50,5) -> 111
A7: 6 | B7: TRP-00006 | C7: 66.2 | D7: 103 | E7: =INDEX(Original_Data!$E$2:$E$50,6) -> 103
A8: 7 | B8: TRP-00007 | C8: 55.4 | D8: 92 | E8: =INDEX(Original_Data!$E$2:$E$50,7) -> 92
A9: 8 | B9: TRP-00008 | C9: 50 | D9: 101 | E9: =INDEX(Original_Data!$E$2:$E$50,8) -> 101
A10: 9 | B10: TRP-00009 | C10: 61.5 | D10: 93 | E10: =INDEX(Original_Data!$E$2:$E$50,9) -> 93
A11: 10 | B11: TRP-00010 | C11: 36.4 | D11: 101 | E11: =INDEX(Original_Data!$E$2:$E$50,10) -> 101

Sheet INDEX_MATCH
A1: Lookup_Trip_ID | B1: Found_Fuel_Efficiency | C1: Fuel_Efficiency | D1: FORMULA USED:
A2: TRP-00001 | B2: 2.67 | C2: =INDEX(Original_Data!$G$2:$G$50,MATCH(A2,Original_Data!$A$2:$A$50,0)) -> 2.67 | D2: =INDEX(Original_Data!$H$2:$H$50,MATCH(A2,Original_Data!$A$2:$A$50,0)) -> 30
A3: TRP-00002 | B3: 3.84 | C3: =INDEX(Original_Data!$G$2:$G$50,MATCH(A3,Original_Data!$A$2:$A$50,0)) -> 3.84 | D3: DESCRIPTION:
A4: TRP-00003 | B4: 3.32 | C4: =INDEX(Original_Data!$G$2:$G$50,MATCH(A4,Original_Data!$A$2:$A$50,0)) -> 3.32 | D4: INDEX-MATCH combination: MATCH finds position of Trip_ID in Original_Data, then INDEX returns corresponding Fuel_Efficiency. More flexible than VLOOKUP. 0 = exact match required.
A5: TRP-00004 | B5: 3.44 | C5: =INDEX(Original_Data!$G$2:$G$50,MATCH(A5,Original_Data!$A$2:$A$50,0)) -> 3.44
A6: TRP-00005 | B6: 2.6 | C6: =INDEX(Original_Data!$G$2:$G$50,MATCH(A6,Original_Data!$A$2:$A$50,0)) -> 2.6

Sheet Statistics
A1: Metric | B1: Calculated_Value | C1: Value | D1: FORMULAS USED:
A2: Avg Fuel Efficiency (KMPL) | B2: 3.43 | C2: =AVERAGE(Original_Data!$G$2:$G$50) -> 3.4302041 | D2: =AVERAGE(Original_Data!$H$2:$H$50) -> 55.204082
A3: Max Fuel Efficiency | B3: 4.37 | C3: =MAX(Original_Data!$G$2:$G$50) -> 4.37 | D3: =MAX(Original_Data!$H$2:$H$50) -> 117
A4: Min Fuel Efficiency | B4: 2.57 | C4: =MIN(Original_Data!$G$2:$G$50) -> 2.57 | D4: =MIN(Original_Data!$H$2:$H$50) -> -8
A5: Avg Delivery Delay (mins) | B5: 55.2 | C5: =AVERAGE(Original_Data!$H$2:$H$50) -> 55.204082 | D5: =COUNTA(Original_Data!$A$2:$A$50) -> 49
A6: Max Delivery Delay | B6: 117 | C6: =MAX(Original_Data!$H$2:$H$50) -> 117 | D6: DESCRIPTION:
A7: Min Delivery Delay | B7: -8 | C7: =MIN(Original_Data!$H$2:$H$50) -> -8 | D7: Statistical functions: AVERAGE (mean), MAX (highest), MIN (lowest), COUNTA (count non-empty cells). Used to calculate summary metrics across entire dataset.
A8: Total Records | B8: 49 | C8: =COUNTA(Original_Data!$A$2:$A$50) -> 49
